<?xml version="1.0"?>
<robot name="cc2019_car" xmlns:xacro="http://www.ros.org/wiki/xacro">
    <!-- Import macros -->
    <!-- <xacro:include filename="$(find realsense_gazebo_plugin)/urdf/realsense-D435.macro.xacro" /> -->
    <xacro:include filename="$(find drive_gazebo_sim)/urdf/hokuyo_urg04lx.macro.xacro"/>
    <xacro:include filename="$(find drive_gazebo_sim)/urdf/pepperl_fuchs_ml100_8_1000_RT.macro.xacro"/>
    <xacro:include filename="$(find drive_gazebo_sim)/urdf/ximea_MQ013MG-ON_SY110.macro.xacro"/>

    <xacro:include filename="$(find carolo)/models/lidar.gazebo"/>
    <xacro:include filename="$(find carolo)/models/camera.gazebo"/>

    <!-- Constants for math -->
    <xacro:property name="PI" value="3.1415926535897931" />
    <!-- Constants for robot dimensions -->
    <xacro:property name="length_wheel" value="0.026" />
    <xacro:property name="radius_wheel" value="0.032" />
    <xacro:property name="length_from_base_to_wheel_y" value="0.088" />
    <xacro:property name="steering_offset" value="0.05" />
    <xacro:property name="mass_scaling_factor" value="10" />
    <xacro:property name="inertia_scaling_factor" value="100" />

    <xacro:macro name="scaled_mass" params="value">
        <mass value="${value * mass_scaling_factor}" />
    </xacro:macro>

    <xacro:macro name="scaled_inertia" params="ixx ixy ixz iyy iyz izz">
        <inertia
            ixx="${ixx * inertia_scaling_factor}"
            ixy="${ixy * inertia_scaling_factor}"
            ixz="${ixz * inertia_scaling_factor}"
            iyy="${iyy * inertia_scaling_factor}"
            iyz="${iyz * inertia_scaling_factor}"
            izz="${izz * inertia_scaling_factor}" />
    </xacro:macro>

   <!-- Wheel macro -->
   <xacro:macro name="steered_wheel" params="right_left reflect_right_left front_rear x_distance">
        <link name="${front_rear}_${right_left}_steer">
            <inertial>
                <xacro:scaled_mass value="0.097624" />
<!--                <inertia ixx="0.03914" ixy="0.001254" ixz="-0.000188347"
                    iyy="0.002881" iyz="-0.0008104685"
                    izz="0.03863" />-->
                    <xacro:scaled_inertia
                        ixx="0.000391"
                        ixy="0.00001125"
                        ixz="0.0"
                        iyy="0.00002881"
                        iyz="0.0"
                        izz="0.0003863" />
            </inertial>
        </link>

        <joint name="chassis_to_${front_rear}_${right_left}_steer" type="revolute">
            <axis xyz="0 0 1"/>
            <parent link="rear_axis_middle"/>
            <child link="${front_rear}_${right_left}_steer"/>
            <origin xyz="${x_distance} ${-reflect_right_left * (length_from_base_to_wheel_y - steering_offset)} ${radius_wheel}"/>
            <dynamics damping="0.01" friction="0.0"/>
            <limit effort="10.0" lower="${-80*PI/180}" upper="${80*PI/180}" velocity="200000000"/> <!--velocity="${20*PI*length_wheel}"/>-->
        </joint>

        <link name="${front_rear}_${right_left}_wheel">
            <visual>
                <origin rpy="${PI/2} ${PI} ${PI/2*(reflect_right_left-1)}" xyz="0 ${-reflect_right_left*length_wheel/2} 0"/>
                <geometry>
                    <mesh filename="package://drive_gazebo_sim/meshes/wheel.dae" scale="1 1 1"/>
                </geometry>
            </visual>
            <collision>
                <origin rpy="${PI/2} 0 0" xyz="0 0 0"/>
                <geometry>
                    <cylinder length="${length_wheel}" radius="${radius_wheel}"/>
                </geometry>
            </collision>
            <inertial>
                <xacro:scaled_mass value="0.049602" />
<!--                <inertia ixx="0.0000285" ixy="6.01*e-10" ixz="6.691*1e-16"
                    iyy="0.00002853" iyz="3.525*1e-16"
                    izz="0.00003704" />-->
                    <xacro:scaled_inertia ixx="0.000285" ixy="0.0" ixz="0.0"
                        iyy="0.0002853" iyz="0.0"
                        izz="0.0003704" />
            </inertial>
        </link>
        <joint name="steer_to_${front_rear}_${right_left}_wheel" type="continuous">
            <axis xyz="0 1 0"/>
            <parent link="${front_rear}_${right_left}_steer"/>
            <child link="${front_rear}_${right_left}_wheel"/>
            <origin xyz="0 ${-reflect_right_left * steering_offset} 0"/>
            <dynamics damping="0.01" friction="0.0"/>
            <limit effort="1.0" velocity="${60000.0*PI/180.0*radius_wheel}"/>
        </joint>

        <!-- Steering transmission -->
        <transmission name="tran_steering_${front_rear}_${right_left}">
            <type>transmission_interface/SimpleTransmission</type>
            <joint name="chassis_to_${front_rear}_${right_left}_steer">
                <hardwareInterface>hardware_interface/EffortJointInterface</hardwareInterface>
            </joint>
            <actuator name="${front_rear}_${right_left}_steer">
                <hardwareInterface>hardware_interface/EffortJointInterface</hardwareInterface>
                <mechanicalReduction>1</mechanicalReduction>
            </actuator>
        </transmission>

        <!-- Wheel transmission -->
        <transmission name="tran_wheel_${front_rear}_${right_left}">
            <type>transmission_interface/SimpleTransmission</type>
            <joint name="steer_to_${front_rear}_${right_left}_wheel">
                <hardwareInterface>hardware_interface/EffortJointInterface</hardwareInterface>
            </joint>
            <actuator name="${front_rear}_${right_left}_wheel">
                <hardwareInterface>hardware_interface/EffortJointInterface</hardwareInterface>
                <mechanicalReduction>1</mechanicalReduction>
            </actuator>
        </transmission>

<!--        <gazebo reference="${front_rear}_${right_left}_wheel">
            <mu1 value="1.0"/>
            <mu2 value="1.0"/>
            <kp value="10.0" />
            <kd value="1.0" />
            <fdir1 value="1 0 0"/>
        </gazebo>-->
    </xacro:macro>

    <!-- Robot -->
    <link name="base_link"/>

    <link name="rear_axis_middle">
      <visual>
        <origin rpy="0 0 ${PI}" xyz="0 0 0" />
        <geometry>
          <mesh filename="package://drive_gazebo_sim/meshes/hull.dae" scale="1 1 1"/>
        </geometry>

      </visual>
      <collision>
        <origin rpy="0 0 0" xyz="0 0 0" />
        <geometry>
          <mesh filename="package://drive_gazebo_sim/meshes/hull_collision.dae" scale="0.001 0.001 0.001"/>
        </geometry>
<!--        <origin rpy="0 0 0" xyz="0.125 0 0.035" />
        <geometry>
          <box size="0.35 0.2 0.055"/>
        </geometry>-->
      </collision>
    </link>

    <joint name="base_joint" type="fixed">
       <parent link="base_link"/>
       <child link="rear_axis_middle"/>
     </joint>

    <joint name="rear_to_chassis" type="fixed">
       <parent link="rear_axis_middle"/>
       <child link="chassis"/>
       <origin xyz="0.110912 0.00420803 0.0422526"/>
     </joint>

    <link name="chassis">
       <inertial>
          <xacro:scaled_mass value="2.051134" />
          <xacro:scaled_inertia ixx="0.01125" ixy="0.0008344" ixz="0.008425"
              iyy="0.04637" iyz="0.00007786"
              izz="0.0449" />
       </inertial>
    </link>

    <joint name="joint_lidar" type="fixed">
      <parent link="chassis"/>
      <child link="lidar"/>
      <origin rpy="0  0  0" xyz="0.065   0.026   0.0085"/>
      <axis xyz="0  0  0"/>
      <limit effort="0" lower="0" upper="0" velocity="0"/>
    </joint>

    <joint name="joint_camera" type="fixed">
      <parent link="chassis"/>
      <child link="camera"/>
      <origin rpy="0  1.571  0" xyz="0.98   0   0.293"/>
      <axis xyz="0  0  0"/>
      <limit effort="0" lower="0" upper="0" velocity="0"/>
    </joint>

    <sensor_hokuyo_urg04lx name="hokuyo" parent="rear_axis_middle" xyz="0.025 0 0.09" rpy="0 0 0"/>
    <sensor_pepperl_fuchs_ml100_8_1000_RT name="pepperl_fuchs" parent="rear_axis_middle" xyz="0.043 -0.0995 0.021" rpy="0 0 ${3*PI/2}"/>
    <sensor_ximea_MQ013MG-ON_SY110 name="ximea" parent="rear_axis_middle" xyz="0.085 0.0 0.255" rpy="${PI} ${-7*PI/6} ${PI}"/>

    <realsense-d435 prefix="realsense" parent="rear_axis_middle">
          <origin xyz="0.02 0 0.105" rpy="0 0 0"/>
    </realsense-d435>

    <xacro:steered_wheel right_left="right" reflect_right_left="1" front_rear="front" x_distance="0.22"/>
    <xacro:steered_wheel right_left="left" reflect_right_left="-1" front_rear="front" x_distance="0.22"/>
    <xacro:steered_wheel right_left="right" reflect_right_left="1" front_rear="rear" x_distance="0.0"/>
    <xacro:steered_wheel right_left="left" reflect_right_left="-1" front_rear="rear" x_distance="0.0"/>

    <gazebo>
      <plugin name="gazebo_ros_control" filename="libgazebo_ros_control.so">
          <robotNamespace>/cc2019_car</robotNamespace>
          <legacyModeNS>false</legacyModeNS>
      </plugin>
    </gazebo>
</robot>
